Workbook

Sheet Read_Me
A1: upay Surokkha+ : Step 8 impact model
A3: Purpose | B3: Estimates the monthly money impact and payback of ScamShield; defines KPIs for Agent Copilot; designs an A/B pilot for Cost Advisor.
A4: WARNING | B4: NO number here is real upay data. Inputs are ASSUMPTIONS (invented placeholders), CONVENTIONS (statistical defaults) or MEASURED_ON_SYNTHETIC (our own Step 2/3 results on synthetic data).
A5: Blue text, yellow fill | B5: Editable input. Change only these cells (sheets Assumptions, CostAdvisor_ABPilot, AgentCopilot_KPIs, and the axis cells in Sensitivity).
A6: Black text | B6: Formula. Do not overwrite.
A7: Green text | B7: Link to another sheet.
A8: Scenarios | B8: Bad / Medium / Good. Bad = pessimistic for benefit (low scam rate, low recall, high false-alarm rate, high costs). Good = optimistic.
A9: Core formula | B9: Prevented loss = monthly transactions x scam rate x average loss x recall x intervention success. Row 'Literal formula' on ScamShield_Model shows it without the intervention factor (set intervention success to 100% to match it).
A10: Net benefit | B10: Prevented loss - false-alarm cost - analyst time cost - customer-friction cost - monthly run cost.
A11: Payback / ROI | B11: Payback = one-time cost / monthly net benefit (only if net > 0). ROI = (net x horizon - one-time cost) / one-time cost.
A12: Sheets | B12: Assumptions | ScamShield_Model | Sensitivity | AgentCopilot_KPIs | CostAdvisor_ABPilot | Sources
A13: Rebuild | B13: python src/impact_model.py (rewrites this workbook and the CSV files from config/impact_assumptions.json)
A14: Currency | B14: BDT (Bangladeshi taka). Fractions are stored as fractions (0.02 = 2%).
A16: Colour legend | B16: Example input cell
B17: Example formula cell
B18: Example cross-sheet link

Sheet Assumptions
A1: Assumptions (edit the blue cells)
A2: Status column: ASSUMPTION = invented placeholder; MEASURED_ON_SYNTHETIC = our own result on synthetic data, not real-world. Sources column = public sources to cite when you replace the placeholder with a real figure.
A4: ID | B4: Group | C4: Assumption | D4: Unit | E4: Bad | F4: Medium | G4: Good | H4: Status | I4: Basis / how it was set | J4: Public sources to cite (see Sources sheet)
A5: V1 | B5: Volume | C5: Monthly transactions scored by ScamShield (in-scope P2P sends) | D5: transactions / month | E5: 10000000 | F5: 10000000 | G5: 10000000 | H5: ASSUMPTION | I5: Placeholder, held equal across scenarios so scenarios isolate model and cost effects. Replace with upay's real monthly P2P send count. | J5: S1: Bangladesh Bank, Mobile Financial Services (MFS) Statistics: Transaction Statistics; S2: upay / UCB annual report and Bangladesh Bank MFS provider-wise statistics
A6: R1 | B6: Scam exposure | C6: Scam rate (share of scored transactions that are loss-causing scams) | D6: fraction | E6: 0.0001 | F6: 0.0003 | G6: 0.0006 | H6: ASSUMPTION | I6: NOT the 2.9% of our synthetic data (that is injected by construction). Real rates are far lower; bad = 0.01%, medium = 0.03%, good = 0.06% are placeholders. | J6: S3: Bangladesh Financial Intelligence Unit (BFIU) annual report; S4: Bangladesh Police / CID cyber-crime statistics and the National Cyber Security Agency; S5: UK Finance, Annual Fraud Report (authorised push payment scams); S6: GSMA, State of the Industry Report on Mobile Money
A7: R2 | B7: Scam exposure | C7: Average loss per scam transaction | D7: BDT | E7: 3000 | F7: 6000 | G7: 10000 | H7: ASSUMPTION | I7: Placeholder. Compute the average P2P ticket from Bangladesh Bank MFS tables (value / number) and compare with victim-reported losses. | J7: S1: Bangladesh Bank, Mobile Financial Services (MFS) Statistics: Transaction Statistics; S3: Bangladesh Financial Intelligence Unit (BFIU) annual report; S4: Bangladesh Police / CID cyber-crime statistics and the National Cyber Security Agency
A8: R3 | B8: Model performance | C8: Recall (share of scam transactions flagged) | D8: fraction | E8: 0.18 | F8: 0.447 | G8: 0.859 | H8: MEASURED_ON_SYNTHETIC | I8: Our own Step 3 numbers on synthetic data: good = Step 2 test split (85.9%), medium = 'Evasion, known scams adapted' (44.7%), bad = 'External validation, all shifts' (18.0%). Real-world recall is unknown. | J8: S7: This project: results/step2_main_results.csv, results/step3_scenarios.csv, models/metrics.json
A9: R4 | B9: Model performance | C9: Intervention success (share of flagged scams where the warning/hold really stops the loss) | D9: fraction | E9: 0.5 | F9: 0.7 | G9: 0.85 | H9: ASSUMPTION | I9: Not measured. Customer may ignore a warning; scammer may re-route. Set it to 100% to get the literal 'volume x rate x loss x recall' formula. | J9: S8: UK Payment Systems Regulator, APP scams performance data; S5: UK Finance, Annual Fraud Report (authorised push payment scams)
A10: F1 | B10: False alarms | C10: False-alarm rate (share of legitimate transactions flagged) | D10: fraction | E10: 0.0677 | F10: 0.0224 | G10: 0.0195 | H10: MEASURED_ON_SYNTHETIC | I10: Own Step 3 numbers: good = Step 2 test split (1.95%), medium = Evasion row (2.24%), bad = External validation (6.77%). | J10: S7: This project: results/step2_main_results.csv, results/step3_scenarios.csv, models/metrics.json
A11: A1 | B11: Analyst time | C11: Share of flags reviewed by a human analyst | D11: fraction | E11: 1 | F11: 1 | G11: 1 | H11: ASSUMPTION | I11: Design rule of the prototype (HIGH cases go to an analyst). Lowering it models triage, but then check the intervention success input. | J11: S9: Your own pilot measurements (time-and-motion study, call-centre tags, cancellation logs, retention)
A12: A2 | B12: Analyst time | C12: Review time per flagged case | D12: minutes | E12: 6 | F12: 4 | G12: 3 | H12: ASSUMPTION | I12: Placeholder. Time a real analyst on 30-50 cases during the pilot. | J12: S9: Your own pilot measurements (time-and-motion study, call-centre tags, cancellation logs, retention)
A13: A3 | B13: Analyst time | C13: Fully loaded monthly cost of one analyst | D13: BDT / month | E13: 45000 | F13: 35000 | G13: 30000 | H13: ASSUMPTION | I13: Placeholder. Use upay HR figure; public check: job-portal salary surveys and BBS wage statistics. | J13: S10: Bangladesh Bureau of Statistics (BBS) wage and labour statistics; job-portal salary surveys; S11: Bangladesh Bank, Monthly Economic Trends / interest-rate statistics
A14: A4 | B14: Analyst time | C14: Paid hours per analyst per month | D14: hours | E14: 176 | F14: 176 | G14: 176 | H14: ASSUMPTION | I14: 22 working days x 8 hours. | J14: S10: Bangladesh Bureau of Statistics (BBS) wage and labour statistics; job-portal salary surveys
A15: A5 | B15: Analyst time | C15: Productive share of paid time (utilization) | D15: fraction | E15: 0.65 | F15: 0.65 | G15: 0.65 | H15: ASSUMPTION | I15: Placeholder; breaks, meetings, idle time between cases. | J15: S9: Your own pilot measurements (time-and-motion study, call-centre tags, cancellation logs, retention)
A16: F2 | B16: False-alarm handling | C16: Notification cost per flag (SMS / push) | D16: BDT | E16: 0.35 | F16: 0.35 | G16: 0.35 | H16: ASSUMPTION | I16: Placeholder; replace with upay's SMS gateway cost. | J16: S12: BTRC (telecom regulator) SMS tariff / your SMS gateway invoice
... A25: H1 | B25: Investment | C25: ROI horizon | D25: months | E25: 12 | F25: 12 | G25: 12 | H25: ASSUMPTION | I25: Chosen by the team; ROI = (net benefit x horizon - one-time cost) / one-time cost. | J25: (team decision)

Sheet ScamShield_Model
A1: ScamShield impact model (monthly, BDT)
A2: All cells are formulas driven by the Assumptions sheet. Inputs are NOT real upay data.
A4: Line | B4: Unit | C4: Bad | D4: Medium | E4: Good | F4: Formula / note
A5: A. Inputs used (linked from Assumptions)
A6: Monthly transactions scored | B6: tx / month | C6: =Assumptions!E5 -> 10000000 | D6: =Assumptions!F5 -> 10000000 | E6: =Assumptions!G5 -> 10000000 | F6: V1
A7: Scam rate | B7: fraction | C7: =Assumptions!E6 -> 0.0001 | D7: =Assumptions!F6 -> 0.0003 | E7: =Assumptions!G6 -> 0.0006 | F7: R1
A8: Average loss per scam | B8: BDT | C8: =Assumptions!E7 -> 3000 | D8: =Assumptions!F7 -> 6000 | E8: =Assumptions!G7 -> 10000 | F8: R2
A9: Recall | B9: fraction | C9: =Assumptions!E8 -> 0.18 | D9: =Assumptions!F8 -> 0.447 | E9: =Assumptions!G8 -> 0.859 | F9: R3 (own Step 2/3 result on synthetic data)
A10: Intervention success | B10: fraction | C10: =Assumptions!E9 -> 0.5 | D10: =Assumptions!F9 -> 0.7 | E10: =Assumptions!G9 -> 0.85 | F10: R4
A11: False-alarm rate | B11: fraction | C11: =Assumptions!E10 -> 0.0677 | D11: =Assumptions!F10 -> 0.0224 | E11: =Assumptions!G10 -> 0.0195 | F11: F1 (own Step 2/3 result on synthetic data)
A12: Share of flags reviewed by analyst | B12: fraction | C12: =Assumptions!E11 -> 1 | D12: =Assumptions!F11 -> 1 | E12: =Assumptions!G11 -> 1 | F12: A1
A13: Review minutes per case | B13: minutes | C13: =Assumptions!E12 -> 6 | D13: =Assumptions!F12 -> 4 | E13: =Assumptions!G12 -> 3 | F13: A2
A14: Analyst monthly cost | B14: BDT / month | C14: =Assumptions!E13 -> 45000 | D14: =Assumptions!F13 -> 35000 | E14: =Assumptions!G13 -> 30000 | F14: A3
A15: Paid hours per month | B15: hours | C15: =Assumptions!E14 -> 176 | D15: =Assumptions!F14 -> 176 | E15: =Assumptions!G14 -> 176 | F15: A4
A16: Utilization | B16: fraction | C16: =Assumptions!E15 -> 0.65 | D16: =Assumptions!F15 -> 0.65 | E16: =Assumptions!G15 -> 0.65 | F16: A5
A17: Notification cost per flag | B17: BDT | C17: =Assumptions!E16 -> 0.35 | D17: =Assumptions!F16 -> 0.35 | E17: =Assumptions!G16 -> 0.35 | F17: F2
... A26: ROI horizon | B26: months | C26: =Assumptions!E25 -> 12 | D26: =Assumptions!F25 -> 12 | E26: =Assumptions!G25 -> 12 | F26: H1
A27: B. Prevented loss
A28: Scam transactions per month | B28: count | C28: =C6*C7 -> 1000 | D28: =D6*D7 -> 3000 | E28: =E6*E7 -> 6000 | F28: volume x scam rate
A29: Legitimate transactions per month | B29: count | C29: =C6-C28 -> 9999000 | D29: =D6-D28 -> 9997000 | E29: =E6-E28 -> 9994000
A30: Total scam loss without ScamShield | B30: BDT | C30: =C28*C8 -> 3000000 | D30: =D28*D8 -> 18000000 | E30: =E28*E8 -> 60000000 | F30: scams x average loss
A31: Literal formula: volume x rate x loss x recall | B31: BDT | C31: =C30*C9 -> 540000 | D31: =D30*D9 -> 8046000 | E31: =E30*E9 -> 51540000 | F31: the formula as specified (intervention success = 100%)
A32: Prevented loss | B32: BDT | C32: =C31*C10 -> 270000 | D32: =D31*D10 -> 5632200 | E32: =E31*E10 -> 43809000 | F32: literal x intervention success
A33: Scams flagged (true positives) | B33: count | C33: =C28*C9 -> 180 | D33: =D28*D9 -> 1341 | E33: =E28*E9 -> 5154
A34: Scams missed | B34: count | C34: =C28-C33 -> 820 | D34: =D28-D33 -> 1659 | E34: =E28-E33 -> 846
A35: C. Costs
A36: False alarms per month | B36: count | C36: =C29*C11 -> 676932.3 | D36: =D29*D11 -> 223932.8 | E36: =E29*E11 -> 194883 | F36: legitimate transactions x false-alarm rate
A37: Total flags | B37: count | C37: =C33+C36 -> 677112.3 | D37: =D33+D36 -> 225273.8 | E37: =E33+E36 -> 200037
A38: Precision at this prevalence | B38: fraction | C38: =IF(C37=0,0,C33/C37) -> 0.00026583478 | D38: =IF(D37=0,0,D33/D37) -> 0.0059527562 | E38: =IF(E37=0,0,E33/E37) -> 0.025765233 | F38: share of flags that are real scams
A39: False-alarm cost (notification + support contact) | B39: BDT | C39: =C36*(C17+C18*C19) -> 2944655.5 | D39: =D36*(D17+D18*D19) -> 414275.68 | E39: =E36*(E17+E18*E19) -> 214371.3 | F39: false alarms x (notification + contact rate x contact cost)
A40: Cases reviewed by analysts | B40: count | C40: =C37*C12 -> 677112.3 | D40: =D37*D12 -> 225273.8 | E40: =E37*E12 -> 200037 | F40: true and false flags both need review
A41: Analyst cost per productive minute | B41: BDT / min | C41: =C14/(C15*60*C16) -> 6.5559441 | D41: =D14/(D15*60*D16) -> 5.0990676 | E41: =E14/(E15*60*E16) -> 4.3706294
A42: Analyst cost per reviewed case | B42: BDT | C42: =C41*C13 -> 39.335664 | D42: =D41*D13 -> 20.39627 | E42: =E41*E13 -> 13.111888
A43: Analyst time cost | B43: BDT | C43: =C40*C42 -> 26634662 | D43: =D40*D42 -> 4594745.3 | E43: =E40*E42 -> 2622862.8 | F43: reviews x cost per review
A44: Customer-friction cost | B44: BDT | C44: =C36*(C20*C21+C22*C23) -> 2166183.4 | D44: =D36*(D20*D21+D22*D23) -> 156752.96 | E44: =E36*(E20*E21+E22*E23) -> 44823.09 | F44: false alarms x (abandonment x lost revenue + churn x customer margin)
A45: Run cost | B45: BDT | C45: =C25 -> 800000 | D45: =D25 -> 500000 | E45: =E25 -> 350000
A46: Analysts needed | B46: FTE | C46: =C40*C13/(C15*60*C16) -> 591.88138 | D46: =D40*D13/(D15*60*D16) -> 131.27844 | E46: =E40*E13/(E15*60*E16) -> 87.428759 | F46: capacity check: can the team really review this many cases?
A47: D. Result
A48: NET MONTHLY BENEFIT | B48: BDT | C48: =C32-C39-C43-C44-C45 -> -32275501 | D48: =D32-D39-D43-D44-D45 -> -33573.978 | E48: =E32-E39-E43-E44-E45 -> 40576943 | F48: prevented loss - false-alarm - analyst - friction - run
A49: PAYBACK | B49: months | C49: =IF(C48>0,C24/C48,"never") -> never | D49: =IF(D48>0,D24/D48,"never") -> never | E49: =IF(E48>0,E24/E48,"never") -> 0.1971563 | F49: one-time cost / net monthly benefit; 'never' if net <= 0
...

Sheet Sensitivity
A1: Sensitivity of monthly net benefit (BDT), Medium scenario
A2: Axis values (blue) are editable. Every other input comes from ScamShield_Model column D (Medium).
A4: Grid 1: recall (across) x false-alarm rate (down)
A5: false-alarm rate \ recall | B5: 0.1 | C5: 0.18 | D5: 0.3 | E5: 0.447 | F5: 0.6 | G5: 0.75 | H5: 0.859
A6: 0.005 | B6: =ScamShield_Model!$D$6*ScamShield_Model!$D$7*B$5*(ScamShield_Model!$D$8*ScamShield_Model!$D$10-ScamShield_Model!$D$12*ScamShield_Model!$D$42)-ScamShield_Model!$D$6*(1-ScamShield_Model!$D$7)*$A6*ScamShield_Model!$D$53-ScamShield_Model!$D$45 -> -393088.21 | C6: =ScamShield_Model!$D$6*ScamShield_Model!$D$7*C$5*(ScamShield_Model!$D$8*ScamShield_Model!$D$10-ScamShield_Model!$D$12*ScamShield_Model!$D$42)-ScamShield_Model!$D$6*(1-ScamShield_Model!$D$7)*$A6*ScamShield_Model!$D$53-ScamShield_Model!$D$45 -> 610016.69 | D6: =ScamShield_Model!$D$6*ScamShield_Model!$D$7*D$5*(ScamShield_Model!$D$8*ScamShield_Model!$D$10-ScamShield_Model!$D$12*ScamShield_Model!$D$42)-ScamShield_Model!$D$6*(1-ScamShield_Model!$D$7)*$A6*ScamShield_Model!$D$53-ScamShield_Model!$D$45 -> 2114674 | E6: =ScamShield_Model!$D$6*ScamShield_Model!$D$7*E$5*(ScamShield_Model!$D$8*ScamShield_Model!$D$10-ScamShield_Model!$D$12*ScamShield_Model!$D$42)-ScamShield_Model!$D$6*(1-ScamShield_Model!$D$7)*$A6*ScamShield_Model!$D$53-ScamShield_Model!$D$45 -> 3957879.3 | F6: =ScamShield_Model!$D$6*ScamShield_Model!$D$7*F$5*(ScamShield_Model!$D$8*ScamShield_Model!$D$10-ScamShield_Model!$D$12*ScamShield_Model!$D$42)-ScamShield_Model!$D$6*(1-ScamShield_Model!$D$7)*$A6*ScamShield_Model!$D$53-ScamShield_Model!$D$45 -> 5876317.4 | G6: =ScamShield_Model!$D$6*ScamShield_Model!$D$7*G$5*(ScamShield_Model!$D$8*ScamShield_Model!$D$10-ScamShield_Model!$D$12*ScamShield_Model!$D$42)-ScamShield_Model!$D$6*(1-ScamShield_Model!$D$7)*$A6*ScamShield_Model!$D$53-ScamShield_Model!$D$45 -> 7757139.1 | H6: =ScamShield_Model!$D$6*ScamShield_Model!$D$7*H$5*(ScamShield_Model!$D$8*ScamShield_Model!$D$10-ScamShield_Model!$D$12*ScamShield_Model!$D$42)-ScamShield_Model!$D$6*(1-ScamShield_Model!$D$7)*$A6*ScamShield_Model!$D$53-ScamShield_Model!$D$45 -> 9123869.5
A7: 0.01 | B7: =ScamShield_Model!$D$6*ScamShield_Model!$D$7*B$5*(ScamShield_Model!$D$8*ScamShield_Model!$D$10-ScamShield_Model!$D$12*ScamShield_Model!$D$42)-ScamShield_Model!$D$6*(1-ScamShield_Model!$D$7)*$A7*ScamShield_Model!$D$53-ScamShield_Model!$D$45 -> -1540057.5 | C7: =ScamShield_Model!$D$6*ScamShield_Model!$D$7*C$5*(ScamShield_Model!$D$8*ScamShield_Model!$D$10-ScamShield_Model!$D$12*ScamShield_Model!$D$42)-ScamShield_Model!$D$6*(1-ScamShield_Model!$D$7)*$A7*ScamShield_Model!$D$53-ScamShield_Model!$D$45 -> -536952.64 | D7: =ScamShield_Model!$D$6*ScamShield_Model!$D$7*D$5*(ScamShield_Model!$D$8*ScamShield_Model!$D$10-ScamShield_Model!$D$12*ScamShield_Model!$D$42)-ScamShield_Model!$D$6*(1-ScamShield_Model!$D$7)*$A7*ScamShield_Model!$D$53-ScamShield_Model!$D$45 -> 967704.71 | E7: =ScamShield_Model!$D$6*ScamShield_Model!$D$7*E$5*(ScamShield_Model!$D$8*ScamShield_Model!$D$10-ScamShield_Model!$D$12*ScamShield_Model!$D$42)-ScamShield_Model!$D$6*(1-ScamShield_Model!$D$7)*$A7*ScamShield_Model!$D$53-ScamShield_Model!$D$45 -> 2810909.9 | F7: =ScamShield_Model!$D$6*ScamShield_Model!$D$7*F$5*(ScamShield_Model!$D$8*ScamShield_Model!$D$10-ScamShield_Model!$D$12*ScamShield_Model!$D$42)-ScamShield_Model!$D$6*(1-ScamShield_Model!$D$7)*$A7*ScamShield_Model!$D$53-ScamShield_Model!$D$45 -> 4729348.1 | G7: =ScamShield_Model!$D$6*ScamShield_Model!$D$7*G$5*(ScamShield_Model!$D$8*ScamShield_Model!$D$10-ScamShield_Model!$D$12*ScamShield_Model!$D$42)-ScamShield_Model!$D$6*(1-ScamShield_Model!$D$7)*$A7*ScamShield_Model!$D$53-ScamShield_Model!$D$45 -> 6610169.7 | H7: =ScamShield_Model!$D$6*ScamShield_Model!$D$7*H$5*(ScamShield_Model!$D$8*ScamShield_Model!$D$10-ScamShield_Model!$D$12*ScamShield_Model!$D$42)-ScamShield_Model!$D$6*(1-ScamShield_Model!$D$7)*$A7*ScamShield_Model!$D$53-ScamShield_Model!$D$45 -> 7976900.2
A8: 0.0195 | B8: =ScamShield_Model!$D$6*ScamShield_Model!$D$7*B$5*(ScamShield_Model!$D$8*ScamShield_Model!$D$10-ScamShield_Model!$D$12*ScamShield_Model!$D$42)-ScamShield_Model!$D$6*(1-ScamShield_Model!$D$7)*$A8*ScamShield_Model!$D$53-ScamShield_Model!$D$45 -> -3719299.3 | C8: =ScamShield_Model!$D$6*ScamShield_Model!$D$7*C$5*(ScamShield_Model!$D$8*ScamShield_Model!$D$10-ScamShield_Model!$D$12*ScamShield_Model!$D$42)-ScamShield_Model!$D$6*(1-ScamShield_Model!$D$7)*$A8*ScamShield_Model!$D$53-ScamShield_Model!$D$45 -> -2716194.4 | D8: =ScamShield_Model!$D$6*ScamShield_Model!$D$7*D$5*(ScamShield_Model!$D$8*ScamShield_Model!$D$10-ScamShield_Model!$D$12*ScamShield_Model!$D$42)-ScamShield_Model!$D$6*(1-ScamShield_Model!$D$7)*$A8*ScamShield_Model!$D$53-ScamShield_Model!$D$45 -> -1211537 | E8: =ScamShield_Model!$D$6*ScamShield_Model!$D$7*E$5*(ScamShield_Model!$D$8*ScamShield_Model!$D$10-ScamShield_Model!$D$12*ScamShield_Model!$D$42)-ScamShield_Model!$D$6*(1-ScamShield_Model!$D$7)*$A8*ScamShield_Model!$D$53-ScamShield_Model!$D$45 -> 631668.23 | F8: =ScamShield_Model!$D$6*ScamShield_Model!$D$7*F$5*(ScamShield_Model!$D$8*ScamShield_Model!$D$10-ScamShield_Model!$D$12*ScamShield_Model!$D$42)-ScamShield_Model!$D$6*(1-ScamShield_Model!$D$7)*$A8*ScamShield_Model!$D$53-ScamShield_Model!$D$45 -> 2550106.3 | G8: =ScamShield_Model!$D$6*ScamShield_Model!$D$7*G$5*(ScamShield_Model!$D$8*ScamShield_Model!$D$10-ScamShield_Model!$D$12*ScamShield_Model!$D$42)-ScamShield_Model!$D$6*(1-ScamShield_Model!$D$7)*$A8*ScamShield_Model!$D$53-ScamShield_Model!$D$45 -> 4430928 | H8: =ScamShield_Model!$D$6*ScamShield_Model!$D$7*H$5*(ScamShield_Model!$D$8*ScamShield_Model!$D$10-ScamShield_Model!$D$12*ScamShield_Model!$D$42)-ScamShield_Model!$D$6*(1-ScamShield_Model!$D$7)*$A8*ScamShield_Model!$D$53-ScamShield_Model!$D$45 -> 5797658.4
A9: 0.0224 | B9: =ScamShield_Model!$D$6*ScamShield_Model!$D$7*B$5*(ScamShield_Model!$D$8*ScamShield_Model!$D$10-ScamShield_Model!$D$12*ScamShield_Model!$D$42)-ScamShield_Model!$D$6*(1-ScamShield_Model!$D$7)*$A9*ScamShield_Model!$D$53-ScamShield_Model!$D$45 -> -4384541.5 | C9: =ScamShield_Model!$D$6*ScamShield_Model!$D$7*C$5*(ScamShield_Model!$D$8*ScamShield_Model!$D$10-ScamShield_Model!$D$12*ScamShield_Model!$D$42)-ScamShield_Model!$D$6*(1-ScamShield_Model!$D$7)*$A9*ScamShield_Model!$D$53-ScamShield_Model!$D$45 -> -3381436.6 | D9: =ScamShield_Model!$D$6*ScamShield_Model!$D$7*D$5*(ScamShield_Model!$D$8*ScamShield_Model!$D$10-ScamShield_Model!$D$12*ScamShield_Model!$D$42)-ScamShield_Model!$D$6*(1-ScamShield_Model!$D$7)*$A9*ScamShield_Model!$D$53-ScamShield_Model!$D$45 -> -1876779.2 | E9: =ScamShield_Model!$D$6*ScamShield_Model!$D$7*E$5*(ScamShield_Model!$D$8*ScamShield_Model!$D$10-ScamShield_Model!$D$12*ScamShield_Model!$D$42)-ScamShield_Model!$D$6*(1-ScamShield_Model!$D$7)*$A9*ScamShield_Model!$D$53-ScamShield_Model!$D$45 -> -33573.978 | F9: =ScamShield_Model!$D$6*ScamShield_Model!$D$7*F$5*(ScamShield_Model!$D$8*ScamShield_Model!$D$10-ScamShield_Model!$D$12*ScamShield_Model!$D$42)-ScamShield_Model!$D$6*(1-ScamShield_Model!$D$7)*$A9*ScamShield_Model!$D$53-ScamShield_Model!$D$45 -> 1884864.1 | G9: =ScamShield_Model!$D$6*ScamShield_Model!$D$7*G$5*(ScamShield_Model!$D$8*ScamShield_Model!$D$10-ScamShield_Model!$D$12*ScamShield_Model!$D$42)-ScamShield_Model!$D$6*(1-ScamShield_Model!$D$7)*$A9*ScamShield_Model!$D$53-ScamShield_Model!$D$45 -> 3765685.8 | H9: =ScamShield_Model!$D$6*ScamShield_Model!$D$7*H$5*(ScamShield_Model!$D$8*ScamShield_Model!$D$10-ScamShield_Model!$D$12*ScamShield_Model!$D$42)-ScamShield_Model!$D$6*(1-ScamShield_Model!$D$7)*$A9*ScamShield_Model!$D$53-ScamShield_Model!$D$45 -> 5132416.2
A10: 0.04 | B10: =ScamShield_Model!$D$6*ScamShield_Model!$D$7*B$5*(ScamShield_Model!$D$8*ScamShield_Model!$D$10-ScamShield_Model!$D$12*ScamShield_Model!$D$42)-ScamShield_Model!$D$6*(1-ScamShield_Model!$D$7)*$A10*ScamShield_Model!$D$53-ScamShield_Model!$D$45 -> -8421873.5 | C10: =ScamShield_Model!$D$6*ScamShield_Model!$D$7*C$5*(ScamShield_Model!$D$8*ScamShield_Model!$D$10-ScamShield_Model!$D$12*ScamShield_Model!$D$42)-ScamShield_Model!$D$6*(1-ScamShield_Model!$D$7)*$A10*ScamShield_Model!$D$53-ScamShield_Model!$D$45 -> -7418768.6 | D10: =ScamShield_Model!$D$6*ScamShield_Model!$D$7*D$5*(ScamShield_Model!$D$8*ScamShield_Model!$D$10-ScamShield_Model!$D$12*ScamShield_Model!$D$42)-ScamShield_Model!$D$6*(1-ScamShield_Model!$D$7)*$A10*ScamShield_Model!$D$53-ScamShield_Model!$D$45 -> -5914111.2 | E10: =ScamShield_Model!$D$6*ScamShield_Model!$D$7*E$5*(ScamShield_Model!$D$8*ScamShield_Model!$D$10-ScamShield_Model!$D$12*ScamShield_Model!$D$42)-ScamShield_Model!$D$6*(1-ScamShield_Model!$D$7)*$A10*ScamShield_Model!$D$53-ScamShield_Model!$D$45 -> -4070906 | F10: =ScamShield_Model!$D$6*ScamShield_Model!$D$7*F$5*(ScamShield_Model!$D$8*ScamShield_Model!$D$10-ScamShield_Model!$D$12*ScamShield_Model!$D$42)-ScamShield_Model!$D$6*(1-ScamShield_Model!$D$7)*$A10*ScamShield_Model!$D$53-ScamShield_Model!$D$45 -> -2152467.9 | G10: =ScamShield_Model!$D$6*ScamShield_Model!$D$7*G$5*(ScamShield_Model!$D$8*ScamShield_Model!$D$10-ScamShield_Model!$D$12*ScamShield_Model!$D$42)-ScamShield_Model!$D$6*(1-ScamShield_Model!$D$7)*$A10*ScamShield_Model!$D$53-ScamShield_Model!$D$45 -> -271646.21 | H10: =ScamShield_Model!$D$6*ScamShield_Model!$D$7*H$5*(ScamShield_Model!$D$8*ScamShield_Model!$D$10-ScamShield_Model!$D$12*ScamShield_Model!$D$42)-ScamShield_Model!$D$6*(1-ScamShield_Model!$D$7)*$A10*ScamShield_Model!$D$53-ScamShield_Model!$D$45 -> 1095084.2
A11: 0.0677 | B11: =ScamShield_Model!$D$6*ScamShield_Model!$D$7*B$5*(ScamShield_Model!$D$8*ScamShield_Model!$D$10-ScamShield_Model!$D$12*ScamShield_Model!$D$42)-ScamShield_Model!$D$6*(1-ScamShield_Model!$D$7)*$A11*ScamShield_Model!$D$53-ScamShield_Model!$D$45 -> -14776084 | C11: =ScamShield_Model!$D$6*ScamShield_Model!$D$7*C$5*(ScamShield_Model!$D$8*ScamShield_Model!$D$10-ScamShield_Model!$D$12*ScamShield_Model!$D$42)-ScamShield_Model!$D$6*(1-ScamShield_Model!$D$7)*$A11*ScamShield_Model!$D$53-ScamShield_Model!$D$45 -> -13772979 | D11: =ScamShield_Model!$D$6*ScamShield_Model!$D$7*D$5*(ScamShield_Model!$D$8*ScamShield_Model!$D$10-ScamShield_Model!$D$12*ScamShield_Model!$D$42)-ScamShield_Model!$D$6*(1-ScamShield_Model!$D$7)*$A11*ScamShield_Model!$D$53-ScamShield_Model!$D$45 -> -12268321 | E11: =ScamShield_Model!$D$6*ScamShield_Model!$D$7*E$5*(ScamShield_Model!$D$8*ScamShield_Model!$D$10-ScamShield_Model!$D$12*ScamShield_Model!$D$42)-ScamShield_Model!$D$6*(1-ScamShield_Model!$D$7)*$A11*ScamShield_Model!$D$53-ScamShield_Model!$D$45 -> -10425116 | F11: =ScamShield_Model!$D$6*ScamShield_Model!$D$7*F$5*(ScamShield_Model!$D$8*ScamShield_Model!$D$10-ScamShield_Model!$D$12*ScamShield_Model!$D$42)-ScamShield_Model!$D$6*(1-ScamShield_Model!$D$7)*$A11*ScamShield_Model!$D$53-ScamShield_Model!$D$45 -> -8506678 | G11: =ScamShield_Model!$D$6*ScamShield_Model!$D$7*G$5*(ScamShield_Model!$D$8*ScamShield_Model!$D$10-ScamShield_Model!$D$12*ScamShield_Model!$D$42)-ScamShield_Model!$D$6*(1-ScamShield_Model!$D$7)*$A11*ScamShield_Model!$D$53-ScamShield_Model!$D$45 -> -6625856.3 | H11: =ScamShield_Model!$D$6*ScamShield_Model!$D$7*H$5*(ScamShield_Model!$D$8*ScamShield_Model!$D$10-ScamShield_Model!$D$12*ScamShield_Model!$D$42)-ScamShield_Model!$D$6*(1-ScamShield_Model!$D$7)*$A11*ScamShield_Model!$D$53-ScamShield_Model!$D$45 -> -5259125.9
A14: Grid 2: scam rate (across) x average loss (down)
A15: average loss \ scam rate | B15: 0.0001 | C15: 0.0002 | D15: 0.0003 | E15: 0.0006 | F15: 0.001
A16: 2000 | B16: =ScamShield_Model!$D$6*B$15*ScamShield_Model!$D$9*($A16*ScamShield_Model!$D$10-ScamShield_Model!$D$12*ScamShield_Model!$D$42)-ScamShield_Model!$D$6*(1-B$15)*ScamShield_Model!$D$11*ScamShield_Model!$D$53-ScamShield_Model!$D$45 -> -5022767.7 | C16: =ScamShield_Model!$D$6*C$15*ScamShield_Model!$D$9*($A16*ScamShield_Model!$D$10-ScamShield_Model!$D$12*ScamShield_Model!$D$42)-ScamShield_Model!$D$6*(1-C$15)*ScamShield_Model!$D$11*ScamShield_Model!$D$53-ScamShield_Model!$D$45 -> -4405570.8 | D16: =ScamShield_Model!$D$6*D$15*ScamShield_Model!$D$9*($A16*ScamShield_Model!$D$10-ScamShield_Model!$D$12*ScamShield_Model!$D$42)-ScamShield_Model!$D$6*(1-D$15)*ScamShield_Model!$D$11*ScamShield_Model!$D$53-ScamShield_Model!$D$45 -> -3788374 | E16: =ScamShield_Model!$D$6*E$15*ScamShield_Model!$D$9*($A16*ScamShield_Model!$D$10-ScamShield_Model!$D$12*ScamShield_Model!$D$42)-ScamShield_Model!$D$6*(1-E$15)*ScamShield_Model!$D$11*ScamShield_Model!$D$53-ScamShield_Model!$D$45 -> -1936783.4 | F16: =ScamShield_Model!$D$6*F$15*ScamShield_Model!$D$9*($A16*ScamShield_Model!$D$10-ScamShield_Model!$D$12*ScamShield_Model!$D$42)-ScamShield_Model!$D$6*(1-F$15)*ScamShield_Model!$D$11*ScamShield_Model!$D$53-ScamShield_Model!$D$45 -> 532004.07
A17: 4000 | B17: =ScamShield_Model!$D$6*B$15*ScamShield_Model!$D$9*($A17*ScamShield_Model!$D$10-ScamShield_Model!$D$12*ScamShield_Model!$D$42)-ScamShield_Model!$D$6*(1-B$15)*ScamShield_Model!$D$11*ScamShield_Model!$D$53-ScamShield_Model!$D$45 -> -4396967.7 | C17: =ScamShield_Model!$D$6*C$15*ScamShield_Model!$D$9*($A17*ScamShield_Model!$D$10-ScamShield_Model!$D$12*ScamShield_Model!$D$42)-ScamShield_Model!$D$6*(1-C$15)*ScamShield_Model!$D$11*ScamShield_Model!$D$53-ScamShield_Model!$D$45 -> -3153970.8 | D17: =ScamShield_Model!$D$6*D$15*ScamShield_Model!$D$9*($A17*ScamShield_Model!$D$10-ScamShield_Model!$D$12*ScamShield_Model!$D$42)-ScamShield_Model!$D$6*(1-D$15)*ScamShield_Model!$D$11*ScamShield_Model!$D$53-ScamShield_Model!$D$45 -> -1910974 | E17: =ScamShield_Model!$D$6*E$15*ScamShield_Model!$D$9*($A17*ScamShield_Model!$D$10-ScamShield_Model!$D$12*ScamShield_Model!$D$42)-ScamShield_Model!$D$6*(1-E$15)*ScamShield_Model!$D$11*ScamShield_Model!$D$53-ScamShield_Model!$D$45 -> 1818016.6 | F17: =ScamShield_Model!$D$6*F$15*ScamShield_Model!$D$9*($A17*ScamShield_Model!$D$10-ScamShield_Model!$D$12*ScamShield_Model!$D$42)-ScamShield_Model!$D$6*(1-F$15)*ScamShield_Model!$D$11*ScamShield_Model!$D$53-ScamShield_Model!$D$45 -> 6790004.1
A18: 6000 | B18: =ScamShield_Model!$D$6*B$15*ScamShield_Model!$D$9*($A18*ScamShield_Model!$D$10-ScamShield_Model!$D$12*ScamShield_Model!$D$42)-ScamShield_Model!$D$6*(1-B$15)*ScamShield_Model!$D$11*ScamShield_Model!$D$53-ScamShield_Model!$D$45 -> -3771167.7 | C18: =ScamShield_Model!$D$6*C$15*ScamShield_Model!$D$9*($A18*ScamShield_Model!$D$10-ScamShield_Model!$D$12*ScamShield_Model!$D$42)-ScamShield_Model!$D$6*(1-C$15)*ScamShield_Model!$D$11*ScamShield_Model!$D$53-ScamShield_Model!$D$45 -> -1902370.8 | D18: =ScamShield_Model!$D$6*D$15*ScamShield_Model!$D$9*($A18*ScamShield_Model!$D$10-ScamShield_Model!$D$12*ScamShield_Model!$D$42)-ScamShield_Model!$D$6*(1-D$15)*ScamShield_Model!$D$11*ScamShield_Model!$D$53-ScamShield_Model!$D$45 -> -33573.978 | E18: =ScamShield_Model!$D$6*E$15*ScamShield_Model!$D$9*($A18*ScamShield_Model!$D$10-ScamShield_Model!$D$12*ScamShield_Model!$D$42)-ScamShield_Model!$D$6*(1-E$15)*ScamShield_Model!$D$11*ScamShield_Model!$D$53-ScamShield_Model!$D$45 -> 5572816.6 | F18: =ScamShield_Model!$D$6*F$15*ScamShield_Model!$D$9*($A18*ScamShield_Model!$D$10-ScamShield_Model!$D$12*ScamShield_Model!$D$42)-ScamShield_Model!$D$6*(1-F$15)*ScamShield_Model!$D$11*ScamShield_Model!$D$53-ScamShield_Model!$D$45 -> 13048004
A19: 10000 | B19: =ScamShield_Model!$D$6*B$15*ScamShield_Model!$D$9*($A19*ScamShield_Model!$D$10-ScamShield_Model!$D$12*ScamShield_Model!$D$42)-ScamShield_Model!$D$6*(1-B$15)*ScamShield_Model!$D$11*ScamShield_Model!$D$53-ScamShield_Model!$D$45 -> -2519567.7 | C19: =ScamShield_Model!$D$6*C$15*ScamShield_Model!$D$9*($A19*ScamShield_Model!$D$10-ScamShield_Model!$D$12*ScamShield_Model!$D$42)-ScamShield_Model!$D$6*(1-C$15)*ScamShield_Model!$D$11*ScamShield_Model!$D$53-ScamShield_Model!$D$45 -> 600829.16 | D19: =ScamShield_Model!$D$6*D$15*ScamShield_Model!$D$9*($A19*ScamShield_Model!$D$10-ScamShield_Model!$D$12*ScamShield_Model!$D$42)-ScamShield_Model!$D$6*(1-D$15)*ScamShield_Model!$D$11*ScamShield_Model!$D$53-ScamShield_Model!$D$45 -> 3721226 | E19: =ScamShield_Model!$D$6*E$15*ScamShield_Model!$D$9*($A19*ScamShield_Model!$D$10-ScamShield_Model!$D$12*ScamShield_Model!$D$42)-ScamShield_Model!$D$6*(1-E$15)*ScamShield_Model!$D$11*ScamShield_Model!$D$53-ScamShield_Model!$D$45 -> 13082417 | F19: =ScamShield_Model!$D$6*F$15*ScamShield_Model!$D$9*($A19*ScamShield_Model!$D$10-ScamShield_Model!$D$12*ScamShield_Model!$D$42)-ScamShield_Model!$D$6*(1-F$15)*ScamShield_Model!$D$11*ScamShield_Model!$D$53-ScamShield_Model!$D$45 -> 25564004
A20: 15000 | B20: =ScamShield_Model!$D$6*B$15*ScamShield_Model!$D$9*($A20*ScamShield_Model!$D$10-ScamShield_Model!$D$12*ScamShield_Model!$D$42)-ScamShield_Model!$D$6*(1-B$15)*ScamShield_Model!$D$11*ScamShield_Model!$D$53-ScamShield_Model!$D$45 -> -955067.71 | C20: =ScamShield_Model!$D$6*C$15*ScamShield_Model!$D$9*($A20*ScamShield_Model!$D$10-ScamShield_Model!$D$12*ScamShield_Model!$D$42)-ScamShield_Model!$D$6*(1-C$15)*ScamShield_Model!$D$11*ScamShield_Model!$D$53-ScamShield_Model!$D$45 -> 3729829.2 | D20: =ScamShield_Model!$D$6*D$15*ScamShield_Model!$D$9*($A20*ScamShield_Model!$D$10-ScamShield_Model!$D$12*ScamShield_Model!$D$42)-ScamShield_Model!$D$6*(1-D$15)*ScamShield_Model!$D$11*ScamShield_Model!$D$53-ScamShield_Model!$D$45 -> 8414726 | E20: =ScamShield_Model!$D$6*E$15*ScamShield_Model!$D$9*($A20*ScamShield_Model!$D$10-ScamShield_Model!$D$12*ScamShield_Model!$D$42)-ScamShield_Model!$D$6*(1-E$15)*ScamShield_Model!$D$11*ScamShield_Model!$D$53-ScamShield_Model!$D$45 -> 22469417 | F20: =ScamShield_Model!$D$6*F$15*ScamShield_Model!$D$9*($A20*ScamShield_Model!$D$10-ScamShield_Model!$D$12*ScamShield_Model!$D$42)-ScamShield_Model!$D$6*(1-F$15)*ScamShield_Model!$D$11*ScamShield_Model!$D$53-ScamShield_Model!$D$45 -> 41209004
A22: Positive = ScamShield earns more than it costs per month. One-at-a-time +/-25% sensitivity of every input is in results/step8_sensitivity_tornado.csv.

Sheet AgentCopilot_KPIs
A1: Agent Copilot: measurable KPIs
A2: Baseline / pilot / target columns hold EXAMPLE values (placeholders; forecast-error row = our synthetic Step 1 result). Replace them with measured values. Design: randomise agents (stratified by area and size) into Copilot on / off for 8 weeks.
A4: KPI | B4: Unit | C4: Better | D4: Definition | E4: Formula | F4: Data needed | G4: Guardrail | H4: Baseline (EXAMPLE) | I4: Pilot (EXAMPLE) | J4: Target change (ASSUMPTION) | K4: Change | L4: Target met? | M4: Status
A5: Stock-out hours | B5: hours / agent / month | C5: lower | D5: Hours in which the agent could not serve a normal cash-out because own cash or e-float was below the minimum service amount, or a cash-out request was declined for insufficient agent balance. | E5: stock-out hours = number of clock hours with (balance < min service amount) OR (>= 1 declined-for-liquidity request); averaged per agent per month | F5: Hourly agent cash/e-float snapshots; log of cash-out requests declined for liquidity; agent opening hours | G5: Do not count hours when the agent was closed. Count only declines caused by liquidity, not by network or fraud holds. | H5: 24 | I5: 16 | J5: -0.2 | K5: =IF(H5=0,0,I5/H5-1) -> -0.33333333 | L5: =IF(C5="higher",K5>=J5,K5<=J5) -> TRUE | M5: EXAMPLE
A6: Completed transactions | B6: cash-out transactions / agent / week | C6: higher | D6: Cash-out transactions completed at the agent, plus the liquidity-failure rate (share of cash-out attempts that failed because the agent lacked cash/float). | E6: completed = count of successful cash-outs per agent-week; liquidity-failure rate = failed-for-liquidity / (completed + failed-for-liquidity) | F6: Transaction log with status and failure reason code, per agent | G6: Compare same weeks of the month (salary week vs non-salary week) between arms. | H6: 310 | I6: 325 | J6: 0.03 | K6: =IF(H6=0,0,I6/H6-1) -> 0.048387097 | L6: =IF(C6="higher",K6>=J6,K6<=J6) -> TRUE | M6: EXAMPLE
A7: Idle cash | B7: BDT / agent (average daily excess buffer) | C7: lower | D7: Average end-of-day cash + float held above what the next 7 days of observed demand needed (excess buffer). Lower is better only if stock-out hours do not rise. | E7: idle cash = mean over days of max(0, end-of-day balance - peak observed 7-day-ahead demand) | F7: End-of-day balances; realised daily cash-out demand per agent | G7: Report idle cash and stock-out hours together; a drop in idle cash with more stock-outs is a failure, not a saving. | H7: 60000 | I7: 52000 | J7: -0.1 | K7: =IF(H7=0,0,I7/H7-1) -> -0.13333333 | L7: =IF(C7="higher",K7>=J7,K7<=J7) -> TRUE | M7: EXAMPLE
A8: Forecast error vs 7-day-average baseline | B8: MAE, BDT per agent-day | C8: lower | D8: Mean absolute error of the 7-day forecast against realised cash-out demand, compared with the simple 7-day average. | E8: MAE = mean(|forecast - actual|); improvement = 1 - MAE_model / MAE_baseline | F8: Daily forecasts stored at issue time; realised daily demand | G8: Example values are our SYNTHETIC Step-1 numbers (about 13% better), not real agent data. | H8: 12256 | I8: 10662 | J8: -0.1 | K8: =IF(H8=0,0,I8/H8-1) -> -0.13005875 | L8: =IF(C8="higher",K8>=J8,K8<=J8) -> TRUE | M8: EXAMPLE
A9: Warning usefulness | B9: share of HIGH warnings followed by a real shortfall | C9: higher | D9: Precision of HIGH cash-shortage warnings and the share of warned agents who actually rebalanced before the predicted date. | E9: warning precision = HIGH warnings followed by a stock-out or near stock-out within 7 days / all HIGH warnings | F9: Warning log; rebalancing (cash-in / float purchase) log; stock-out log | G9: Too many unnecessary warnings make agents ignore the tool; track warnings per agent per week. | H9: 0.3 | I9: 0.45 | J9: 0.1 | K9: =I9-H9 -> 0.15 | L9: =IF(C9="higher",K9>=J9,K9<=J9) -> TRUE | M9: EXAMPLE
A11: Notes
A12: 'Change' is relative (pilot / baseline - 1) except 'Warning usefulness', which is the percentage-point difference.
A13: Read stock-out hours, completed transactions and idle cash TOGETHER: lower idle cash with more stock-outs is a failure.
A14: The synthetic dataset has no cash balances, so these KPIs can only be measured in a real pilot with hourly balance snapshots and failure-reason codes.
A15: Sources to cite for context and baselines: S14 (agent-network surveys), S1 (Bangladesh Bank MFS statistics), S15-S16 (experiment design), S11 (cost of funds).

Sheet CostAdvisor_ABPilot
A1: Cost Advisor: A/B pilot to measure REAL fee savings
A2: No migration rate is assumed anywhere. Migration and savings are measured outputs of the pilot (section 3).
A4: 1. Design
A5: Element | B5: Design
A6: Question | B6: How much do customers really save in fees, and how many small cash-outs really move to digital payments, when they see a Cost Advisor message? No migration rate is assumed: it is an OUTPUT of the pilot.
A7: Unit of randomisation | B7: Customer, stratified by Cost Advisor segment (low / regular / frequent) and by area (urban / rural). Use the agent or village as the unit instead if customers share agents and spill-over is likely.
A8: Eligibility | B8: Customers with at least 2 cash-outs under the small-cash-out limit in the 8-12 week pre-period, active in the last 30 days, not flagged by ScamShield, with message consent.
A9: Arms | B9: Control = no message (true holdout). Treatment = Cost Advisor message. Optional arm B = message plus a small incentive, only if the team wants to price the incentive.
A10: Allocation | B10: 1:1 random assignment with a fixed seed written down before launch; check balance on pre-period fees, segment and area before launch (A/A check).
A11: Duration | B11: At least 8 weeks (two or more salary-week cycles). Do not stop early because an interim result looks good.
A12: Primary metric | B12: Net fees paid on cash-outs per customer-month (BDT), treatment minus control, intention-to-treat. Variance reduction with the pre-period value (CUPED) if the correlation is known.
A13: Secondary metrics | B13: Migration = share of eligible small cash-out value that moved to digital payments (measured, not assumed); count and value of digital payments; cash-out count.
A14: Upay-side metric | B14: Net revenue per customer-month: fees on cash-outs + merchant discount earned - incentives. A customer saving is a revenue transfer unless merchant revenue makes up for it.
A15: Guardrails | B15: Complaint rate, message opt-outs, total transaction value (must not fall), active-customer rate, cash-out failure rate. Any guardrail breach pauses the arm.
A16: Analysis | B16: Pre-registered. Difference in means with 95% confidence interval (template in the workbook). Report ITT first; treatment-on-treated only as a supplement.
... A18: Ethics and wording | B18: Message states a possible saving honestly and is optional advice; no pressure, no hiding of cash-out. Control customers get the message after the pilot if it works.
A20: 2. Sample size (edit blue cells)
A21: Input | B21: Value | C21: Unit | D21: Status | E21: Basis | F21: Public sources to cite
A22: B1 Significance level alpha (two-sided) | B22: 0.05 | C22: fraction | D22: CONVENTION | E22: Standard experiment convention; change only if the team pre-registers a different value. | F22: S15: Kohavi, Tang, Xu, Trustworthy Online Controlled Experiments (Cambridge University Press, 2020)
A23: B2 Statistical power (1 - beta) | B23: 0.8 | C23: fraction | D23: CONVENTION | E23: Standard experiment convention. | F23: S15: Kohavi, Tang, Xu, Trustworthy Online Controlled Experiments (Cambridge University Press, 2020); S16: Duflo, Glennerster, Kremer, Using Randomization in Development Economics Research: A Toolkit (2007)
A24: B3 Std. deviation of fees paid per eligible customer-month | B24: 19 | C24: BDT | D24: MEASURED_ON_SYNTHETIC | E24: Computed on our synthetic data (std of monthly fee on cash-outs under BDT 1,500, using the ASSUMED 1.4% rate). Replace with the std from 8-12 weeks of real pre-period data. | F24: S9: Your own pilot measurements (time-and-motion study, call-centre tags, cancellation logs, retention); S15: Kohavi, Tang, Xu, Trustworthy Online Controlled Experiments (Cambridge University Press, 2020)
A25: B4 Minimum detectable effect (saving per customer-month) | B25: 2 | C25: BDT | D25: ASSUMPTION | E25: Smallest saving worth acting on. Choose with the business team; smaller MDE needs many more customers. | F25: S13: upay official tariff page / app charges and Bangladesh Bank circulars on MFS charges; S15: Kohavi, Tang, Xu, Trustworthy Online Controlled Experiments (Cambridge University Press, 2020)
A26: B5 Correlation between pre-period and pilot-period fees (for CUPED) | B26: 0.5 | C26: fraction | D26: ASSUMPTION | E26: Measure on real pre-period data. Set to 0 to disable variance reduction. | F26: S17: Deng, Xu, Kohavi, Walker, Improving the Sensitivity of Online Controlled Experiments by Utilizing Pre-Experiment Data (CUPED, WSDM 2013)
A27: B6 Expected attrition / missing data | B27: 0.1 | C27: fraction | D27: ASSUMPTION | E27: Customers who become inactive or unreachable during the pilot. | F27: S16: Duflo, Glennerster, Kremer, Using Randomization in Development Economics Research: A Toolkit (2007)
A28: B7 Eligible customer base available for the pilot | B28: 50000 | C28: customers | D28: ASSUMPTION | E28: Replace with the real count of customers having at least 2 small cash-outs in the pre-period. | F28: S2: upay / UCB annual report and Bangladesh Bank MFS provider-wise statistics; S9: Your own pilot measurements (time-and-motion study, call-centre tags, cancellation logs, retention)
A29: B8 Pilot duration | B29: 8 | C29: weeks | D29: ASSUMPTION | E29: At least two salary-week cycles; cash-out behaviour is strongly calendar-dependent. | F29: S16: Duflo, Glennerster, Kremer, Using Randomization in Development Economics Research: A Toolkit (2007)
A30: B9 Cash-out fee rate (customer pays at agent) | B30: 0.014 | C30: fraction of amount | D30: ASSUMPTION | E30: Same prototype assumption as src/cashout_saver.py; a 2021 press report quoted upay at 1.4% for USSD agent cash-out. NOT confirmed as the current tariff. | F30: S13: upay official tariff page / app charges and Bangladesh Bank circulars on MFS charges
A31: B10 Customer fee on the digital alternative (merchant payment) | B31: 0 | C31: fraction of amount | D31: ASSUMPTION | E31: Merchant payments are often free to the payer; check the tariff. | F31: S13: upay official tariff page / app charges and Bangladesh Bank circulars on MFS charges
A32: B11 Merchant discount rate earned by upay on migrated value | B32: 0.005 | C32: fraction of amount | D32: ASSUMPTION | E32: Placeholder; use upay's merchant pricing. | F32: S2: upay / UCB annual report and Bangladesh Bank MFS provider-wise statistics; S13: upay official tariff page / app charges and Bangladesh Bank circulars on MFS charges
A33: B12 Small cash-out limit defining eligible cash-outs | B33: 1500 | C33: BDT | D33: ASSUMPTION | E33: Equals SMALL_LIMIT in src/cashout_saver.py. | F33: S13: upay official tariff page / app charges and Bangladesh Bank circulars on MFS charges
A34: z (alpha/2) + z (power) | B34: =NORMSINV(1-$B$22/2)+NORMSINV($B$23) -> 2.8015852
A35: Customers needed per arm | B35: =ROUNDUP(2*B34^2*$B$24^2*(1-$B$26^2)/$B$25^2,0) -> 1063 | E35: n = 2 (z_a/2 + z_b)^2 sigma^2 (1 - rho^2) / MDE^2 (normal approximation)
A36: Customers to enrol (both arms, after attrition) | B36: =ROUNDUP(2*B35/(1-$B$27),0) -> 2363
A37: Enough eligible customers? | B37: =IF($B$28>=B36,"yes","no: raise MDE, extend duration or widen eligibility") -> yes
A39: 3. Analysis template (enter pilot results; values below are EXAMPLES)
A40: Quantity | B40: Value | C40: Unit | D40: Status | E40: How to get it
A41: Treatment customers analysed | B41: 1100 | C41: customers | D41: EXAMPLE | E41: count after attrition
A42: Control customers analysed | B42: 1090 | C42: customers | D42: EXAMPLE | E42: count after attrition
A43: Mean fees paid per customer-month, treatment | B43: 27 | C43: BDT | D43: EXAMPLE | E43: fees on cash-outs, pilot period (CUPED-adjusted if used)
A44: Mean fees paid per customer-month, control | B44: 29 | C44: BDT | D44: EXAMPLE | E44: same definition
...

Sheet Sources
A1: Public sources to cite for each input
A2: Only S1 was seen live (2026-10-07). For every other source open it, copy the exact figure, edition and date, and cite that. Do not cite a source for a number you did not read in it.
A4: ID | B4: Source | C4: Where | D4: What to take from it | E4: Used for inputs | F4: Note
A5: S1 | B5: Bangladesh Bank, Mobile Financial Services (MFS) Statistics: Transaction Statistics | C5: https://www.bb.org.bd/econdata/fin_digitalfstat/tab9.pdf | D5: Industry transaction counts and values; derive average ticket size and a plausible upay share. Monthly counts are in the hundreds of millions industry-wide. | E5: V1, R2 | F5: Link appeared in a web search on 2026-10-07 with data up to May 2026. Open it and confirm the table before citing.
A6: S2 | B6: upay / UCB annual report and Bangladesh Bank MFS provider-wise statistics | C6: https://www.bb.org.bd (search 'MFS statistics') | D6: Upay's own volume, active customers, revenue. Prefer the company's own internal figure. | E6: V1, C4, B7, B11 | F6: Link/edition NOT re-verified. Open the source, note the exact figure, edition and date, then cite.
A7: S3 | B7: Bangladesh Financial Intelligence Unit (BFIU) annual report | C7: https://www.bfiu.org.bd | D7: Suspicious-transaction reports and typologies involving MFS; verify the current edition. | E7: R1, R2 | F7: Link/edition NOT re-verified. Open the source, note the exact figure, edition and date, then cite.
A8: S4 | B8: Bangladesh Police / CID cyber-crime statistics and the National Cyber Security Agency | C8: https://www.police.gov.bd (verify current page) | D8: Reported MFS-related fraud cases and losses; reported cases understate true incidence. | E8: R1, R2 | F8: Link/edition NOT re-verified. Open the source, note the exact figure, edition and date, then cite.
A9: S5 | B9: UK Finance, Annual Fraud Report (authorised push payment scams) | C9: https://www.ukfinance.org.uk | D9: International benchmark for APP-scam counts, values and share recovered; use only as a cross-check, not as a Bangladesh figure. | E9: R1, R4 | F9: Link/edition NOT re-verified. Open the source, note the exact figure, edition and date, then cite.
A10: S6 | B10: GSMA, State of the Industry Report on Mobile Money | C10: https://www.gsma.com/sotir | D10: Mobile-money fraud and consumer-protection context across markets. | E10: R1 | F10: Link/edition NOT re-verified. Open the source, note the exact figure, edition and date, then cite.
A11: S7 | B11: This project: results/step2_main_results.csv, results/step3_scenarios.csv, models/metrics.json | C11: (in repository) | D11: Recall and false-alarm rate. Synthetic data; say so whenever you cite them. | E11: R3, F1 | F11: Internal source.
A12: S8 | B12: UK Payment Systems Regulator, APP scams performance data | C12: https://www.psr.org.uk | D12: Share of APP-scam losses recovered or reimbursed; indicates how often a flagged payment can really be stopped. | E12: R4 | F12: Link/edition NOT re-verified. Open the source, note the exact figure, edition and date, then cite.
A13: S9 | B13: Your own pilot measurements (time-and-motion study, call-centre tags, cancellation logs, retention) | C13: (internal) | D13: The only credible source for analyst minutes, support contacts, abandonment and churn. | E13: A1, A2, A5, F3, F4, C1, C3, B3, B7 | F13: Internal source.
A14: S10 | B14: Bangladesh Bureau of Statistics (BBS) wage and labour statistics; job-portal salary surveys | C14: https://bbs.gov.bd | D14: Salary level for analysts and call-centre staff; cross-check against upay HR. | E14: A3, A4, F4, K1, K2 | F14: Link/edition NOT re-verified. Open the source, note the exact figure, edition and date, then cite.
A15: S11 | B15: Bangladesh Bank, Monthly Economic Trends / interest-rate statistics | C15: https://www.bb.org.bd | D15: Cost of funds for idle-cash valuation (Agent Copilot calculator). | E15: A3 | F15: Link/edition NOT re-verified. Open the source, note the exact figure, edition and date, then cite.
... A17: S13 | B17: upay official tariff page / app charges and Bangladesh Bank circulars on MFS charges | C17: https://www.upaybd.com (verify current tariff) | D17: Send-money and cash-out fee schedule. A news report states Bangladesh Bank sets no fixed cash-out cap, so the provider's own tariff is the authority. | E17: C2, C4, B4, B9, B10, B11, B12 | F17: Link/edition NOT re-verified. Open the source, note the exact figure, edition and date, then cite.
A18: S14 | B18: Helix Institute of Digital Finance / InterMedia agent-network surveys (Bangladesh) | C18: https://www.helix-institute.com (verify availability) | D18: Agent liquidity problems, stock-out frequency, agent commission levels. | F18: Link/edition NOT re-verified. Open the source, note the exact figure, edition and date, then cite.
A19: S15 | B19: Kohavi, Tang, Xu, Trustworthy Online Controlled Experiments (Cambridge University Press, 2020) | C19: (book) | D19: A/B test design, sample size, guardrail metrics. | E19: B1, B2, B3, B4 | F19: Link/edition NOT re-verified. Open the source, note the exact figure, edition and date, then cite.
A20: S16 | B20: Duflo, Glennerster, Kremer, Using Randomization in Development Economics Research: A Toolkit (2007) | C20: https://economics.mit.edu (search the title) | D20: Randomization units, stratification, spillovers, power. | E20: B2, B6, B8 | F20: Link/edition NOT re-verified. Open the source, note the exact figure, edition and date, then cite.
A21: S17 | B21: Deng, Xu, Kohavi, Walker, Improving the Sensitivity of Online Controlled Experiments by Utilizing Pre-Experiment Data (CUPED, WSDM 2013) | C21: (paper) | D21: Variance reduction with pre-period data. | E21: B5 | F21: Link/edition NOT re-verified. Open the source, note the exact figure, edition and date, then cite.
